Traceback (most recent call last):
  File "c:\users\andi\appdata\local\programs\python\python38\lib\site-packages\jupyter_cache\executors\utils.py", line 51, in single_nb_execution
    executenb(
  File "c:\users\andi\appdata\local\programs\python\python38\lib\site-packages\nbclient\client.py", line 1112, in execute
    return NotebookClient(nb=nb, resources=resources, km=km, **kwargs).execute()
  File "c:\users\andi\appdata\local\programs\python\python38\lib\site-packages\nbclient\util.py", line 74, in wrapped
    return just_run(coro(*args, **kwargs))
  File "c:\users\andi\appdata\local\programs\python\python38\lib\site-packages\nbclient\util.py", line 53, in just_run
    return loop.run_until_complete(coro)
  File "c:\users\andi\appdata\local\programs\python\python38\lib\asyncio\base_events.py", line 612, in run_until_complete
    return future.result()
  File "c:\users\andi\appdata\local\programs\python\python38\lib\site-packages\nbclient\client.py", line 553, in async_execute
    await self.async_execute_cell(
  File "c:\users\andi\appdata\local\programs\python\python38\lib\site-packages\nbclient\client.py", line 857, in async_execute_cell
    self._check_raise_for_error(cell, exec_reply)
  File "c:\users\andi\appdata\local\programs\python\python38\lib\site-packages\nbclient\client.py", line 760, in _check_raise_for_error
    raise CellExecutionError.from_cell_and_msg(cell, exec_reply_content)
nbclient.exceptions.CellExecutionError: An error occurred while executing the following cell:
------------------
import numpy as np
import sympy
import sympy as sym
from sympy import init_printing
import warnings

warnings.filterwarnings("ignore", category=UserWarning)
from IPython.display import display, Math

x1, x2, x3 = sym.symbols('x1, x2, x3')
x = sym.Matrix([[x1], [x2], [x3]])
Q = sym.Matrix([[1, 0, 0], [0, 1, 0], [0, 0, 0.1]])
c = sym.Matrix([[0], [0], [0.55]])
------------------

[1;31m---------------------------------------------------------------------------[0m
[1;31mModuleNotFoundError[0m                       Traceback (most recent call last)
[1;32m<ipython-input-1-7a080d3bcbfd>[0m in [0;36m<module>[1;34m[0m
[0;32m      1[0m [1;32mimport[0m [0mnumpy[0m [1;32mas[0m [0mnp[0m[1;33m[0m[1;33m[0m[0m
[1;32m----> 2[1;33m [1;32mimport[0m [0msympy[0m[1;33m[0m[1;33m[0m[0m
[0m[0;32m      3[0m [1;32mimport[0m [0msympy[0m [1;32mas[0m [0msym[0m[1;33m[0m[1;33m[0m[0m
[0;32m      4[0m [1;32mfrom[0m [0msympy[0m [1;32mimport[0m [0minit_printing[0m[1;33m[0m[1;33m[0m[0m
[0;32m      5[0m [1;32mimport[0m [0mwarnings[0m[1;33m[0m[1;33m[0m[0m

[1;31mModuleNotFoundError[0m: No module named 'sympy'
ModuleNotFoundError: No module named 'sympy'

