Traceback (most recent call last):
  File "c:\users\andi\appdata\local\programs\python\python38\lib\site-packages\jupyter_cache\executors\utils.py", line 51, in single_nb_execution
    executenb(
  File "c:\users\andi\appdata\local\programs\python\python38\lib\site-packages\nbclient\client.py", line 1112, in execute
    return NotebookClient(nb=nb, resources=resources, km=km, **kwargs).execute()
  File "c:\users\andi\appdata\local\programs\python\python38\lib\site-packages\nbclient\util.py", line 74, in wrapped
    return just_run(coro(*args, **kwargs))
  File "c:\users\andi\appdata\local\programs\python\python38\lib\site-packages\nbclient\util.py", line 53, in just_run
    return loop.run_until_complete(coro)
  File "c:\users\andi\appdata\local\programs\python\python38\lib\asyncio\base_events.py", line 612, in run_until_complete
    return future.result()
  File "c:\users\andi\appdata\local\programs\python\python38\lib\site-packages\nbclient\client.py", line 553, in async_execute
    await self.async_execute_cell(
  File "c:\users\andi\appdata\local\programs\python\python38\lib\site-packages\nbclient\client.py", line 857, in async_execute_cell
    self._check_raise_for_error(cell, exec_reply)
  File "c:\users\andi\appdata\local\programs\python\python38\lib\site-packages\nbclient\client.py", line 760, in _check_raise_for_error
    raise CellExecutionError.from_cell_and_msg(cell, exec_reply_content)
nbclient.exceptions.CellExecutionError: An error occurred while executing the following cell:
------------------
import sys
sys.path.append(r"C:\Users\DULLA\PycharmProjects\Thesis_Data_Analisys")
from random import seed, randint
from time import process_time

import matplotlib.image as mpimg
import matplotlib.pyplot as plt
import networkx as nx
import numpy as np

from CMST_package.population_generator import draw_graph, generate_population, TREE_LIKE_LAYOUT, breeding_mutation, \
self_mutation, prim, measure_branch

# MODIFICAMI!
NUM_NODES = 10
NUMB_GENER = 300
MESH_LIKE_LAYOUT = 0
HOF_SIZE = 3
MAXIMUM_FITNESS = 1000
POP_SIZE = 100
SELF_MUTATE_PROB = 0.3
CROSS_MUTATE_PROB = 0.7
ROOT = 5
CAPACITY = 4

#img = mpimg.imread('../artifacts/flowchart.PNG')
#plt.figure(figsize=(12, 12))
#plt.axis("off")

#imgplot = plt.imshow(img)
------------------

[1;31m---------------------------------------------------------------------------[0m
[1;31mModuleNotFoundError[0m                       Traceback (most recent call last)
[1;32m<ipython-input-1-2ab02361eb81>[0m in [0;36m<module>[1;34m[0m
[0;32m      9[0m [1;32mimport[0m [0mnumpy[0m [1;32mas[0m [0mnp[0m[1;33m[0m[1;33m[0m[0m
[0;32m     10[0m [1;33m[0m[0m
[1;32m---> 11[1;33m [1;32mfrom[0m [0mCMST_package[0m[1;33m.[0m[0mpopulation_generator[0m [1;32mimport[0m [0mdraw_graph[0m[1;33m,[0m [0mgenerate_population[0m[1;33m,[0m [0mTREE_LIKE_LAYOUT[0m[1;33m,[0m [0mbreeding_mutation[0m[1;33m,[0m[0;31m [0m[0;31m\[0m[1;33m[0m[1;33m[0m[0m
[0m[0;32m     12[0m [0mself_mutation[0m[1;33m,[0m [0mprim[0m[1;33m,[0m [0mmeasure_branch[0m[1;33m[0m[1;33m[0m[0m
[0;32m     13[0m [1;33m[0m[0m

[1;31mModuleNotFoundError[0m: No module named 'CMST_package'
ModuleNotFoundError: No module named 'CMST_package'

